Workbook
Name guarantors_cleaned: 'Applications (Corrected Dates)'!$A$1:$M$8038
Name properties_cleaned: Properties!$A$1:$H$1537
Name properties_cleaned: 'Properties (Cleaned)'!$A$1:$G$1537

Sheet Applications
A1: app_id | B1: property_id | C1: app_date | D1: employment_status | E1: income | F1: credit_score | G1: previously_evicted | H1: has_cosigner | I1: approval_status | J1: premium | K1: monthly_rent | L1: tenants | M1: notes
A2: 140 | B2: 357 | C2: 43996 | D2: Retired | E2: 129141 | G2: No | H2: no | I2: Denied | J2: 5846.4 | K2: 6090 | L2: 3 | M2: Renewal case.
A3: 339 | B3: 1135 | C3: 45346 | D3: Retired | E3: 227525 | G3: No | H3: TRUE | I3: approved | J3: 2572.8 | K3: 2680 | L3: 5
A4: 664 | B4: 438 | C4: 44617 | D4: Full-Time | E4: 163743 | F4: 745 | G4: No | H4: TRUE | I4: Approved | J4: 2805.6 | K4: 3340 | L4: 4 | M4: Applicant provided pay stubs.
A5: 1365 | B5: 557 | C5: 24/04/2022 | D5: Contract | E5: 70375 | F5: 687 | G5: No | H5: No | I5: Pending | J5: 2134.2 | K5: 3557 | L5: 4 | M5: Referred by agent.
A6: 2528 | B6: 38 | C6: 44243 | D6: Retired | E6: 142283 | G6: Yes | H6: TRUE | I6: Pending | J6: 4979.52 | K6: 5187 | L6: 5 | M6: Referred by agent.
A7: 5110 | B7: 483 | C7: 43918 | D7: Self-Employed | E7: 168958 | F7: 676 | G7: No | I7: Approved | J7: 1337.28 | K7: 1592 | L7: 2 | M7: Co-signer pending review.
A8: 8277 | B8: 386 | C8: 45320 | D8: Student | E8: 98060 | F8: 833 | G8: No | H8: yes | I8: Approved | J8: 1518 | K8: 2300 | L8: 2 | M8: Flagged for manual review.
A9: 8386 | B9: 1432 | C9: 44092 | D9: Unemployed | E9: 124900000 | F9: 698 | G9: No | H9: No | I9: Under Review | J9: 5827.2 | K9: 6070 | L9: 4 | M9: .
A10: 9442 | B10: 1532 | C10: 44990 | D10: Full-Time | E10: 44834 | F10: 656 | G10: No | H10: No | I10: Denied | J10: 2118.48 | K10: 2716 | L10: 4 | M10: docs expired
A11: 10126 | B11: 207 | C11: 44519 | D11: Retired | E11: 205761 | F11: 662 | G11: No | H11: yes | I11: Pending | J11: 3986.4 | K11: 6644 | L11: 5 | M11: n/a
A12: 12726 | B12: 1738 | C12: 45651 | D12: Part-Time | E12: 213156 | F12: N/A | G12: No | H12: No | I12: Pending | J12: 1776.6 | K12: 2115 | L12: 3 | M12: docs expired
A13: 13509 | B13: 200 | C13: 30/11/2021 | D13: Full-Time | E13: 205434 | G13: Yes | H13: Y | I13: approved | J13: 1840.74 | K13: 2789 | L13: 1 | M13: Referred by agent.
A14: 14294 | B14: 30 | C14: 44970 | D14: Unemployed | E14: 231909 | F14: 809 | G14: No | H14: no | I14: Approved | J14: 2976.96 | K14: 3101 | L14: 4 | M14: Missing bank statements.
A15: 14569 | B15: 304 | C15: 45411 | D15: Unemployed | E15: 183128 | F15: 798 | G15: Yes | H15: No | I15: Denied | J15: 1251 | K15: 2085 | L15: 1 | M15: docs expired
A16: 14590 | B16: 71 | C16: 44625 | D16: Full-Time | E16: 135994 | F16: 448 | G16: No | I16: Pending | J16: 2827.5 | K16: 3625 | L16: 3 | M16: N/A
A17: 16578 | B17: 941 | C17: 44135 | D17: Full-Time | E17: 212683 | F17: 654 | G17: Yes | H17: No | I17: Approved | J17: 2230.02 | K17: 2859 | L17: 3 | M17: n/a
A18: 17022 | B18: 1471 | C18: 44026 | D18: Part-Time | E18: 75089 | G18: No | H18: no | I18: Approved | J18: 3880.8 | K18: 4620 | L18: 3 | M18: Applicant provided pay stubs.
A19: 20568 | B19: 1143 | C19: 13/04/2022 | D19: Retired | E19: 242708 | F19: 497 | G19: No | H19: no | I19: Denied | J19: 2398.08 | K19: 2498 | L19: 1 | M19: Missing bank statements.
A20: 22043 | B20: 1082 | C20: 44303 | D20: Part-Time | E20: 167814 | F20: 722 | G20: No | H20: no | I20: denied | J20: 913.44 | K20: 1384 | L20: 3 | M20: Flagged for manual review.
A21: 22113 | B21: 1614 | C21: 44861 | D21: Full-Time | E21: 161093 | F21: 779 | G21: No | H21: 1 | I21: Pending | J21: 6505.8 | K21: 7745 | L21: 1 | M21: Co-signer pending review.
A22: 22530 | B22: 105 | C22: 27/12/2022 | D22: Unemployed | E22: 243086 | F22: 811 | G22: No | H22: N | I22: Withdrawn | J22: 4456.92 | K22: 5714 | L22: 1 | M22: N/A
A23: 22927 | B23: 858 | C23: 44391 | D23: Unemployed | E23: 6344 | F23: 657 | G23: No | H23: FALSE | I23: denied | J23: 4003.74 | K23: 5133 | L23: 2 | M23: Missing bank statements.
A24: 23053 | B24: 587 | C24: 45339 | D24: Part-Time | E24: 97725 | F24: 447 | G24: No | H24: 1 | I24: Pending | J24: 5443.2 | K24: 5670 | L24: 5 | M24: Co-signer pending review.
A25: 23531 | B25: 623 | D25: Unemployed | E25: 59619 | F25: 770 | G25: No | H25: FALSE | I25: Approved | J25: 7350.72 | K25: 7657 | L25: 2 | M25: Applicant follow-up needed
A26: 25929 | B26: 1112 | C26: 45657 | D26: Student | E26: 18094 | G26: No | H26: No | I26: Pending | J26: 1285.68 | K26: 1948 | L26: 3 | M26: Renewal case.
A27: 27031 | B27: 1424 | C27: 45094 | D27: Student | E27: 117184 | F27: 842 | G27: Yes | H27: 0 | I27: Pending | J27: 1940.64 | K27: 2488 | L27: 5 | M27: N/A
A28: 28523 | B28: 863 | D28: Contract | E28: 129953 | F28: 729 | G28: No | H28: FALSE | I28: Approved | J28: 828.96 | K28: 1256 | L28: 2
A29: 29155 | B29: 117 | C29: 44535 | D29: Student | E29: 67801 | F29: 726 | G29: No | H29: yes | I29: Denied | J29: 1776.06 | K29: 2691 | L29: 5 | M29: Flagged for manual review.
A30: 29469 | B30: 1502 | C30: 43926 | D30: Retired | E30: 205970 | F30: 717 | G30: No | H30: No | I30: Approved | J30: 1761 | K30: 2935 | L30: 1 | M30: N/A
A31: 31153 | B31: 1426 | C31: 45271 | D31: Retired | E31: 239937 | F31: 552 | G31: No | H31: 0 | I31: Approved | J31: 6846.72 | K31: 7132 | L31: 5 | M31: Missing bank statements.
A32: 32569 | B32: 960 | C32: 26/06/2021 | D32: Unemployed | E32: 135402 | F32: 659 | G32: No | H32: N | I32: Denied | J32: 1281.06 | K32: 1941 | L32: 2
A33: 33505 | B33: 1374 | C33: 44776 | D33: Student | E33: 123900000 | F33: 718 | G33: Yes | H33: No | I33: Denied | J33: 2250.6 | K33: 3751 | L33: 5 | M33: Renewal case.
A34: 39831 | B34: 786 | C34: 45412 | D34: Part-Time | E34: 182546 | G34: No | I34: Withdrawn | J34: 1992.48 | K34: 2372 | L34: 4 | M34: n/a
A35: 40594 | B35: 1486 | C35: 44747 | D35: Part-Time | E35: 196804 | F35: 831 | G35: No | H35: FALSE | I35: Pending | J35: 3932.16 | K35: 4096 | L35: 2 | M35: Co-signer pending review.
A36: 40885 | B36: 542 | C36: 45612 | D36: Retired | E36: 79240 | F36: 730 | G36: Yes | H36: TRUE | I36: Pending | J36: 1566.6 | K36: 1865 | L36: 3 | M36: Missing bank statements.
A37: 42664 | B37: 690 | C37: 44177 | D37: Unemployed | E37: 73906 | F37: 632 | G37: No | H37: No | I37: Withdrawn | J37: 1048.32 | K37: 1344 | L37: 2 | M37: Missing bank statements.
A38: 42801 | B38: 1301 | C38: 44733 | D38: Student | E38: 88287 | F38: 587 | G38: No | H38: TRUE | I38: Denied | J38: 1393.92 | K38: 2112 | L38: 5
A39: 42852 | B39: 635 | C39: 45116 | D39: Student | E39: 184446 | F39: 679 | G39: No | H39: 0 | I39: Approved | J39: 4816.32 | K39: 5017 | L39: 2 | M39: .
A40: 45209 | B40: 1679 | C40: 43941 | D40: Student | E40: 155017 | F40: 628 | G40: Yes | H40: FALSE | I40: Withdrawn | J40: 3724.56 | K40: 4434 | L40: 4
...

Sheet Applications (Cleaned)
A1: app_id | B1: property_id | C1: app_date | D1: employment_status | E1: income | F1: credit_score | G1: previously_evicted | H1: has_cosigner | I1: approval_status | J1: premium | K1: monthly_rent | L1: tenants | M1: notes
A2: =TEXT(Applications!A2,"00000") -> 00140 | B2: =TEXT(Applications!B2,"0000") -> 0357 | C2: 43996 | D2: Retired | E2: =LEFT(Applications!E2,6) -> 129141 | G2: No | H2: {=_xlfn.IFS(OR(Applications!H2=FALSE,Applications!H2=0,LEFT(Applications!H2,1)="N"),"No",OR(Applications!H2=TRUE,Applications!H2=1,LEFT(Applications!H2,1)="Y"),"Yes")} -> No | I2: =PROPER(Applications!I2) -> Denied | J2: 5846.4 | K2: 6090 | L2: 3 | M2: Renewal case.
A3: =TEXT(Applications!A3,"00000") -> 00339 | B3: =TEXT(Applications!B3,"0000") -> 1135 | C3: 45346 | D3: Retired | E3: =LEFT(Applications!E3,6) -> 227525 | G3: No | H3: {=_xlfn.IFS(OR(Applications!H3=FALSE,Applications!H3=0,LEFT(Applications!H3,1)="N"),"No",OR(Applications!H3=TRUE,Applications!H3=1,LEFT(Applications!H3,1)="Y"),"Yes")} -> Yes | I3: =PROPER(Applications!I3) -> Approved | J3: 2572.8 | K3: 2680 | L3: 5
A4: =TEXT(Applications!A4,"00000") -> 00664 | B4: =TEXT(Applications!B4,"0000") -> 0438 | C4: 44617 | D4: Full-Time | E4: =LEFT(Applications!E4,6) -> 163743 | F4: 745 | G4: No | H4: {=_xlfn.IFS(OR(Applications!H4=FALSE,Applications!H4=0,LEFT(Applications!H4,1)="N"),"No",OR(Applications!H4=TRUE,Applications!H4=1,LEFT(Applications!H4,1)="Y"),"Yes")} -> Yes | I4: =PROPER(Applications!I4) -> Approved | J4: 2805.6 | K4: 3340 | L4: 4 | M4: Applicant provided pay stubs.
A5: =TEXT(Applications!A5,"00000") -> 01365 | B5: =TEXT(Applications!B5,"0000") -> 0557 | C5: 24/04/2022 | D5: Contract | E5: =LEFT(Applications!E5,6) -> 70375 | F5: 687 | G5: No | H5: {=_xlfn.IFS(OR(Applications!H5=FALSE,Applications!H5=0,LEFT(Applications!H5,1)="N"),"No",OR(Applications!H5=TRUE,Applications!H5=1,LEFT(Applications!H5,1)="Y"),"Yes")} -> No | I5: =PROPER(Applications!I5) -> Pending | J5: 2134.2 | K5: 3557 | L5: 4 | M5: Referred by agent.
A6: =TEXT(Applications!A6,"00000") -> 02528 | B6: =TEXT(Applications!B6,"0000") -> 0038 | C6: 44243 | D6: Retired | E6: =LEFT(Applications!E6,6) -> 142283 | G6: Yes | H6: {=_xlfn.IFS(OR(Applications!H6=FALSE,Applications!H6=0,LEFT(Applications!H6,1)="N"),"No",OR(Applications!H6=TRUE,Applications!H6=1,LEFT(Applications!H6,1)="Y"),"Yes")} -> Yes | I6: =PROPER(Applications!I6) -> Pending | J6: 4979.52 | K6: 5187 | L6: 5 | M6: Referred by agent.
A7: =TEXT(Applications!A7,"00000") -> 05110 | B7: =TEXT(Applications!B7,"0000") -> 0483 | C7: 43918 | D7: Self-Employed | E7: =LEFT(Applications!E7,6) -> 168958 | F7: 676 | G7: No | H7: {=_xlfn.IFS(OR(Applications!H7=FALSE,Applications!H7=0,LEFT(Applications!H7,1)="N"),"No",OR(Applications!H7=TRUE,Applications!H7=1,LEFT(Applications!H7,1)="Y"),"Yes")} -> No | I7: =PROPER(Applications!I7) -> Approved | J7: 1337.28 | K7: 1592 | L7: 2 | M7: Co-signer pending review.
A8: =TEXT(Applications!A8,"00000") -> 08277 | B8: =TEXT(Applications!B8,"0000") -> 0386 | C8: 45320 | D8: Student | E8: =LEFT(Applications!E8,6) -> 98060 | F8: 833 | G8: No | H8: {=_xlfn.IFS(OR(Applications!H8=FALSE,Applications!H8=0,LEFT(Applications!H8,1)="N"),"No",OR(Applications!H8=TRUE,Applications!H8=1,LEFT(Applications!H8,1)="Y"),"Yes")} -> Yes | I8: =PROPER(Applications!I8) -> Approved | J8: 1518 | K8: 2300 | L8: 2 | M8: Flagged for manual review.
A9: =TEXT(Applications!A9,"00000") -> 08386 | B9: =TEXT(Applications!B9,"0000") -> 1432 | C9: 44092 | D9: Unemployed | E9: =LEFT(Applications!E9,6) -> 124900 | F9: 698 | G9: No | H9: {=_xlfn.IFS(OR(Applications!H9=FALSE,Applications!H9=0,LEFT(Applications!H9,1)="N"),"No",OR(Applications!H9=TRUE,Applications!H9=1,LEFT(Applications!H9,1)="Y"),"Yes")} -> No | I9: =PROPER(Applications!I9) -> Under Review | J9: 5827.2 | K9: 6070 | L9: 4 | M9: .
A10: =TEXT(Applications!A10,"00000") -> 09442 | B10: =TEXT(Applications!B10,"0000") -> 1532 | C10: 44990 | D10: Full-Time | E10: =LEFT(Applications!E10,6) -> 44834 | F10: 656 | G10: No | H10: {=_xlfn.IFS(OR(Applications!H10=FALSE,Applications!H10=0,LEFT(Applications!H10,1)="N"),"No",OR(Applications!H10=TRUE,Applications!H10=1,LEFT(Applications!H10,1)="Y"),"Yes")} -> No | I10: =PROPER(Applications!I10) -> Denied | J10: 2118.48 | K10: 2716 | L10: 4 | M10: docs expired
A11: =TEXT(Applications!A11,"00000") -> 10126 | B11: =TEXT(Applications!B11,"0000") -> 0207 | C11: 44519 | D11: Retired | E11: =LEFT(Applications!E11,6) -> 205761 | F11: 662 | G11: No | H11: {=_xlfn.IFS(OR(Applications!H11=FALSE,Applications!H11=0,LEFT(Applications!H11,1)="N"),"No",OR(Applications!H11=TRUE,Applications!H11=1,LEFT(Applications!H11,1)="Y"),"Yes")} -> Yes | I11: =PROPER(Applications!I11) -> Pending | J11: 3986.4 | K11: 6644 | L11: 5 | M11: n/a
A12: =TEXT(Applications!A12,"00000") -> 12726 | B12: =TEXT(Applications!B12,"0000") -> 1738 | C12: 45651 | D12: Part-Time | E12: =LEFT(Applications!E12,6) -> 213156 | F12: N/A | G12: No | H12: {=_xlfn.IFS(OR(Applications!H12=FALSE,Applications!H12=0,LEFT(Applications!H12,1)="N"),"No",OR(Applications!H12=TRUE,Applications!H12=1,LEFT(Applications!H12,1)="Y"),"Yes")} -> No | I12: =PROPER(Applications!I12) -> Pending | J12: 1776.6 | K12: 2115 | L12: 3 | M12: docs expired
A13: =TEXT(Applications!A13,"00000") -> 13509 | B13: =TEXT(Applications!B13,"0000") -> 0200 | C13: 30/11/2021 | D13: Full-Time | E13: =LEFT(Applications!E13,6) -> 205434 | G13: Yes | H13: {=_xlfn.IFS(OR(Applications!H13=FALSE,Applications!H13=0,LEFT(Applications!H13,1)="N"),"No",OR(Applications!H13=TRUE,Applications!H13=1,LEFT(Applications!H13,1)="Y"),"Yes")} -> Yes | I13: =PROPER(Applications!I13) -> Approved | J13: 1840.74 | K13: 2789 | L13: 1 | M13: Referred by agent.
A14: =TEXT(Applications!A14,"00000") -> 14294 | B14: =TEXT(Applications!B14,"0000") -> 0030 | C14: 44970 | D14: Unemployed | E14: =LEFT(Applications!E14,6) -> 231909 | F14: 809 | G14: No | H14: {=_xlfn.IFS(OR(Applications!H14=FALSE,Applications!H14=0,LEFT(Applications!H14,1)="N"),"No",OR(Applications!H14=TRUE,Applications!H14=1,LEFT(Applications!H14,1)="Y"),"Yes")} -> No | I14: =PROPER(Applications!I14) -> Approved | J14: 2976.96 | K14: 3101 | L14: 4 | M14: Missing bank statements.
A15: =TEXT(Applications!A15,"00000") -> 14569 | B15: =TEXT(Applications!B15,"0000") -> 0304 | C15: 45411 | D15: Unemployed | E15: =LEFT(Applications!E15,6) -> 183128 | F15: 798 | G15: Yes | H15: {=_xlfn.IFS(OR(Applications!H15=FALSE,Applications!H15=0,LEFT(Applications!H15,1)="N"),"No",OR(Applications!H15=TRUE,Applications!H15=1,LEFT(Applications!H15,1)="Y"),"Yes")} -> No | I15: =PROPER(Applications!I15) -> Denied | J15: 1251 | K15: 2085 | L15: 1 | M15: docs expired
A16: =TEXT(Applications!A16,"00000") -> 14590 | B16: =TEXT(Applications!B16,"0000") -> 0071 | C16: 44625 | D16: Full-Time | E16: =LEFT(Applications!E16,6) -> 135994 | F16: 448 | G16: No | H16: {=_xlfn.IFS(OR(Applications!H16=FALSE,Applications!H16=0,LEFT(Applications!H16,1)="N"),"No",OR(Applications!H16=TRUE,Applications!H16=1,LEFT(Applications!H16,1)="Y"),"Yes")} -> No | I16: =PROPER(Applications!I16) -> Pending | J16: 2827.5 | K16: 3625 | L16: 3 | M16: N/A
A17: =TEXT(Applications!A17,"00000") -> 16578 | B17: =TEXT(Applications!B17,"0000") -> 0941 | C17: 44135 | D17: Full-Time | E17: =LEFT(Applications!E17,6) -> 212683 | F17: 654 | G17: Yes | H17: {=_xlfn.IFS(OR(Applications!H17=FALSE,Applications!H17=0,LEFT(Applications!H17,1)="N"),"No",OR(Applications!H17=TRUE,Applications!H17=1,LEFT(Applications!H17,1)="Y"),"Yes")} -> No | I17: =PROPER(Applications!I17) -> Approved | J17: 2230.02 | K17: 2859 | L17: 3 | M17: n/a
A18: =TEXT(Applications!A18,"00000") -> 17022 | B18: =TEXT(Applications!B18,"0000") -> 1471 | C18: 44026 | D18: Part-Time | E18: =LEFT(Applications!E18,6) -> 75089 | G18: No | H18: {=_xlfn.IFS(OR(Applications!H18=FALSE,Applications!H18=0,LEFT(Applications!H18,1)="N"),"No",OR(Applications!H18=TRUE,Applications!H18=1,LEFT(Applications!H18,1)="Y"),"Yes")} -> No | I18: =PROPER(Applications!I18) -> Approved | J18: 3880.8 | K18: 4620 | L18: 3 | M18: Applicant provided pay stubs.
A19: =TEXT(Applications!A19,"00000") -> 20568 | B19: =TEXT(Applications!B19,"0000") -> 1143 | C19: 13/04/2022 | D19: Retired | E19: =LEFT(Applications!E19,6) -> 242708 | F19: 497 | G19: No | H19: {=_xlfn.IFS(OR(Applications!H19=FALSE,Applications!H19=0,LEFT(Applications!H19,1)="N"),"No",OR(Applications!H19=TRUE,Applications!H19=1,LEFT(Applications!H19,1)="Y"),"Yes")} -> No | I19: =PROPER(Applications!I19) -> Denied | J19: 2398.08 | K19: 2498 | L19: 1 | M19: Missing bank statements.
A20: =TEXT(Applications!A20,"00000") -> 22043 | B20: =TEXT(Applications!B20,"0000") -> 1082 | C20: 44303 | D20: Part-Time | E20: =LEFT(Applications!E20,6) -> 167814 | F20: 722 | G20: No | H20: {=_xlfn.IFS(OR(Applications!H20=FALSE,Applications!H20=0,LEFT(Applications!H20,1)="N"),"No",OR(Applications!H20=TRUE,Applications!H20=1,LEFT(Applications!H20,1)="Y"),"Yes")} -> No | I20: =PROPER(Applications!I20) -> Denied | J20: 913.44 | K20: 1384 | L20: 3 | M20: Flagged for manual review.
A21: =TEXT(Applications!A21,"00000") -> 22113 | B21: =TEXT(Applications!B21,"0000") -> 1614 | C21: 44861 | D21: Full-Time | E21: =LEFT(Applications!E21,6) -> 161093 | F21: 779 | G21: No | H21: {=_xlfn.IFS(OR(Applications!H21=FALSE,Applications!H21=0,LEFT(Applications!H21,1)="N"),"No",OR(Applications!H21=TRUE,Applications!H21=1,LEFT(Applications!H21,1)="Y"),"Yes")} -> Yes | I21: =PROPER(Applications!I21) -> Pending | J21: 6505.8 | K21: 7745 | L21: 1 | M21: Co-signer pending review.
A22: =TEXT(Applications!A22,"00000") -> 22530 | B22: =TEXT(Applications!B22,"0000") -> 0105 | C22: 27/12/2022 | D22: Unemployed | E22: =LEFT(Applications!E22,6) -> 243086 | F22: 811 | G22: No | H22: {=_xlfn.IFS(OR(Applications!H22=FALSE,Applications!H22=0,LEFT(Applications!H22,1)="N"),"No",OR(Applications!H22=TRUE,Applications!H22=1,LEFT(Applications!H22,1)="Y"),"Yes")} -> No | I22: =PROPER(Applications!I22) -> Withdrawn | J22: 4456.92 | K22: 5714 | L22: 1 | M22: N/A
A23: =TEXT(Applications!A23,"00000") -> 22927 | B23: =TEXT(Applications!B23,"0000") -> 0858 | C23: 44391 | D23: Unemployed | E23: =LEFT(Applications!E23,6) -> 6344 | F23: 657 | G23: No | H23: {=_xlfn.IFS(OR(Applications!H23=FALSE,Applications!H23=0,LEFT(Applications!H23,1)="N"),"No",OR(Applications!H23=TRUE,Applications!H23=1,LEFT(Applications!H23,1)="Y"),"Yes")} -> No | I23: =PROPER(Applications!I23) -> Denied | J23: 4003.74 | K23: 5133 | L23: 2 | M23: Missing bank statements.
A24: =TEXT(Applications!A24,"00000") -> 23053 | B24: =TEXT(Applications!B24,"0000") -> 0587 | C24: 45339 | D24: Part-Time | E24: =LEFT(Applications!E24,6) -> 97725 | F24: 447 | G24: No | H24: {=_xlfn.IFS(OR(Applications!H24=FALSE,Applications!H24=0,LEFT(Applications!H24,1)="N"),"No",OR(Applications!H24=TRUE,Applications!H24=1,LEFT(Applications!H24,1)="Y"),"Yes")} -> Yes | I24: =PROPER(Applications!I24) -> Pending | J24: 5443.2 | K24: 5670 | L24: 5 | M24: Co-signer pending review.
A25: =TEXT(Applications!A25,"00000") -> 23531 | B25: =TEXT(Applications!B25,"0000") -> 0623 | D25: Unemployed | E25: =LEFT(Applications!E25,6) -> 59619 | F25: 770 | G25: No | H25: {=_xlfn.IFS(OR(Applications!H25=FALSE,Applications!H25=0,LEFT(Applications!H25,1)="N"),"No",OR(Applications!H25=TRUE,Applications!H25=1,LEFT(Applications!H25,1)="Y"),"Yes")} -> No | I25: =PROPER(Applications!I25) -> Approved | J25: 7350.72 | K25: 7657 | L25: 2 | M25: Applicant follow-up needed
A26: =TEXT(Applications!A26,"00000") -> 25929 | B26: =TEXT(Applications!B26,"0000") -> 1112 | C26: 45657 | D26: Student | E26: =LEFT(Applications!E26,6) -> 18094 | G26: No | H26: {=_xlfn.IFS(OR(Applications!H26=FALSE,Applications!H26=0,LEFT(Applications!H26,1)="N"),"No",OR(Applications!H26=TRUE,Applications!H26=1,LEFT(Applications!H26,1)="Y"),"Yes")} -> No | I26: =PROPER(Applications!I26) -> Pending | J26: 1285.68 | K26: 1948 | L26: 3 | M26: Renewal case.
A27: =TEXT(Applications!A27,"00000") -> 27031 | B27: =TEXT(Applications!B27,"0000") -> 1424 | C27: 45094 | D27: Student | E27: =LEFT(Applications!E27,6) -> 117184 | F27: 842 | G27: Yes | H27: {=_xlfn.IFS(OR(Applications!H27=FALSE,Applications!H27=0,LEFT(Applications!H27,1)="N"),"No",OR(Applications!H27=TRUE,Applications!H27=1,LEFT(Applications!H27,1)="Y"),"Yes")} -> No | I27: =PROPER(Applications!I27) -> Pending | J27: 1940.64 | K27: 2488 | L27: 5 | M27: N/A
A28: =TEXT(Applications!A28,"00000") -> 28523 | B28: =TEXT(Applications!B28,"0000") -> 0863 | D28: Contract | E28: =LEFT(Applications!E28,6) -> 129953 | F28: 729 | G28: No | H28: {=_xlfn.IFS(OR(Applications!H28=FALSE,Applications!H28=0,LEFT(Applications!H28,1)="N"),"No",OR(Applications!H28=TRUE,Applications!H28=1,LEFT(Applications!H28,1)="Y"),"Yes")} -> No | I28: =PROPER(Applications!I28) -> Approved | J28: 828.96 | K28: 1256 | L28: 2
A29: =TEXT(Applications!A29,"00000") -> 29155 | B29: =TEXT(Applications!B29,"0000") -> 0117 | C29: 44535 | D29: Student | E29: =LEFT(Applications!E29,6) -> 67801 | F29: 726 | G29: No | H29: {=_xlfn.IFS(OR(Applications!H29=FALSE,Applications!H29=0,LEFT(Applications!H29,1)="N"),"No",OR(Applications!H29=TRUE,Applications!H29=1,LEFT(Applications!H29,1)="Y"),"Yes")} -> Yes | I29: =PROPER(Applications!I29) -> Denied | J29: 1776.06 | K29: 2691 | L29: 5 | M29: Flagged for manual review.
A30: =TEXT(Applications!A30,"00000") -> 29469 | B30: =TEXT(Applications!B30,"0000") -> 1502 | C30: 43926 | D30: Retired | E30: =LEFT(Applications!E30,6) -> 205970 | F30: 717 | G30: No | H30: {=_xlfn.IFS(OR(Applications!H30=FALSE,Applications!H30=0,LEFT(Applications!H30,1)="N"),"No",OR(Applications!H30=TRUE,Applications!H30=1,LEFT(Applications!H30,1)="Y"),"Yes")} -> No | I30: =PROPER(Applications!I30) -> Approved | J30: 1761 | K30: 2935 | L30: 1 | M30: N/A
A31: =TEXT(Applications!A31,"00000") -> 31153 | B31: =TEXT(Applications!B31,"0000") -> 1426 | C31: 45271 | D31: Retired | E31: =LEFT(Applications!E31,6) -> 239937 | F31: 552 | G31: No | H31: {=_xlfn.IFS(OR(Applications!H31=FALSE,Applications!H31=0,LEFT(Applications!H31,1)="N"),"No",OR(Applications!H31=TRUE,Applications!H31=1,LEFT(Applications!H31,1)="Y"),"Yes")} -> No | I31: =PROPER(Applications!I31) -> Approved | J31: 6846.72 | K31: 7132 | L31: 5 | M31: Missing bank statements.
A32: =TEXT(Applications!A32,"00000") -> 32569 | B32: =TEXT(Applications!B32,"0000") -> 0960 | C32: 26/06/2021 | D32: Unemployed | E32: =LEFT(Applications!E32,6) -> 135402 | F32: 659 | G32: No | H32: {=_xlfn.IFS(OR(Applications!H32=FALSE,Applications!H32=0,LEFT(Applications!H32,1)="N"),"No",OR(Applications!H32=TRUE,Applications!H32=1,LEFT(Applications!H32,1)="Y"),"Yes")} -> No | I32: =PROPER(Applications!I32) -> Denied | J32: 1281.06 | K32: 1941 | L32: 2
A33: =TEXT(Applications!A33,"00000") -> 33505 | B33: =TEXT(Applications!B33,"0000") -> 1374 | C33: 44776 | D33: Student | E33: =LEFT(Applications!E33,6) -> 123900 | F33: 718 | G33: Yes | H33: {=_xlfn.IFS(OR(Applications!H33=FALSE,Applications!H33=0,LEFT(Applications!H33,1)="N"),"No",OR(Applications!H33=TRUE,Applications!H33=1,LEFT(Applications!H33,1)="Y"),"Yes")} -> No | I33: =PROPER(Applications!I33) -> Denied | J33: 2250.6 | K33: 3751 | L33: 5 | M33: Renewal case.
A34: =TEXT(Applications!A34,"00000") -> 39831 | B34: =TEXT(Applications!B34,"0000") -> 0786 | C34: 45412 | D34: Part-Time | E34: =LEFT(Applications!E34,6) -> 182546 | G34: No | H34: {=_xlfn.IFS(OR(Applications!H34=FALSE,Applications!H34=0,LEFT(Applications!H34,1)="N"),"No",OR(Applications!H34=TRUE,Applications!H34=1,LEFT(Applications!H34,1)="Y"),"Yes")} -> No | I34: =PROPER(Applications!I34) -> Withdrawn | J34: 1992.48 | K34: 2372 | L34: 4 | M34: n/a
A35: =TEXT(Applications!A35,"00000") -> 40594 | B35: =TEXT(Applications!B35,"0000") -> 1486 | C35: 44747 | D35: Part-Time | E35: =LEFT(Applications!E35,6) -> 196804 | F35: 831 | G35: No | H35: {=_xlfn.IFS(OR(Applications!H35=FALSE,Applications!H35=0,LEFT(Applications!H35,1)="N"),"No",OR(Applications!H35=TRUE,Applications!H35=1,LEFT(Applications!H35,1)="Y"),"Yes")} -> No | I35: =PROPER(Applications!I35) -> Pending | J35: 3932.16 | K35: 4096 | L35: 2 | M35: Co-signer pending review.
A36: =TEXT(Applications!A36,"00000") -> 40885 | B36: =TEXT(Applications!B36,"0000") -> 0542 | C36: 45612 | D36: Retired | E36: =LEFT(Applications!E36,6) -> 79240 | F36: 730 | G36: Yes | H36: {=_xlfn.IFS(OR(Applications!H36=FALSE,Applications!H36=0,LEFT(Applications!H36,1)="N"),"No",OR(Applications!H36=TRUE,Applications!H36=1,LEFT(Applications!H36,1)="Y"),"Yes")} -> Yes | I36: =PROPER(Applications!I36) -> Pending | J36: 1566.6 | K36: 1865 | L36: 3 | M36: Missing bank statements.
A37: =TEXT(Applications!A37,"00000") -> 42664 | B37: =TEXT(Applications!B37,"0000") -> 0690 | C37: 44177 | D37: Unemployed | E37: =LEFT(Applications!E37,6) -> 73906 | F37: 632 | G37: No | H37: {=_xlfn.IFS(OR(Applications!H37=FALSE,Applications!H37=0,LEFT(Applications!H37,1)="N"),"No",OR(Applications!H37=TRUE,Applications!H37=1,LEFT(Applications!H37,1)="Y"),"Yes")} -> No | I37: =PROPER(Applications!I37) -> Withdrawn | J37: 1048.32 | K37: 1344 | L37: 2 | M37: Missing bank statements.
A38: =TEXT(Applications!A38,"00000") -> 42801 | B38: =TEXT(Applications!B38,"0000") -> 1301 | C38: 44733 | D38: Student | E38: =LEFT(Applications!E38,6) -> 88287 | F38: 587 | G38: No | H38: {=_xlfn.IFS(OR(Applications!H38=FALSE,Applications!H38=0,LEFT(Applications!H38,1)="N"),"No",OR(Applications!H38=TRUE,Applications!H38=1,LEFT(Applications!H38,1)="Y"),"Yes")} -> Yes | I38: =PROPER(Applications!I38) -> Denied | J38: 1393.92 | K38: 2112 | L38: 5
A39: =TEXT(Applications!A39,"00000") -> 42852 | B39: =TEXT(Applications!B39,"0000") -> 0635 | C39: 45116 | D39: Student | E39: =LEFT(Applications!E39,6) -> 184446 | F39: 679 | G39: No | H39: {=_xlfn.IFS(OR(Applications!H39=FALSE,Applications!H39=0,LEFT(Applications!H39,1)="N"),"No",OR(Applications!H39=TRUE,Applications!H39=1,LEFT(Applications!H39,1)="Y"),"Yes")} -> No | I39: =PROPER(Applications!I39) -> Approved | J39: 4816.32 | K39: 5017 | L39: 2 | M39: .
A40: =TEXT(Applications!A40,"00000") -> 45209 | B40: =TEXT(Applications!B40,"0000") -> 1679 | C40: 43941 | D40: Student | E40: =LEFT(Applications!E40,6) -> 155017 | F40: 628 | G40: Yes | H40: {=_xlfn.IFS(OR(Applications!H40=FALSE,Applications!H40=0,LEFT(Applications!H40,1)="N"),"No",OR(Applications!H40=TRUE,Applications!H40=1,LEFT(Applications!H40,1)="Y"),"Yes")} -> No | I40: =PROPER(Applications!I40) -> Withdrawn | J40: 3724.56 | K40: 4434 | L40: 4
...

Sheet Applications (Corrected Dates)
A1: app_id | B1: property_id | C1: app_date | D1: employment_status | E1: income | F1: credit_score | G1: previously_evicted | H1: has_cosigner | I1: approval_status | J1: premium | K1: monthly_rent | L1: tenants | M1: notes
A2: ='Applications (Cleaned)'!A2 -> 00140 | B2: ='Applications (Cleaned)'!B2 -> 0357 | C2: 43996 | D2: Retired | E2: 129141 | G2: No | H2: No | I2: Denied | J2: 5846.4 | K2: 6090 | L2: 3 | M2: Renewal case.
A3: ='Applications (Cleaned)'!A3 -> 00339 | B3: ='Applications (Cleaned)'!B3 -> 1135 | C3: 45346 | D3: Retired | E3: 227525 | G3: No | H3: Yes | I3: Approved | J3: 2572.8 | K3: 2680 | L3: 5
A4: ='Applications (Cleaned)'!A4 -> 00664 | B4: ='Applications (Cleaned)'!B4 -> 0438 | C4: 44617 | D4: Full-Time | E4: 163743 | F4: 745 | G4: No | H4: Yes | I4: Approved | J4: 2805.6 | K4: 3340 | L4: 4 | M4: Applicant provided pay stubs.
A5: ='Applications (Cleaned)'!A5 -> 01365 | B5: ='Applications (Cleaned)'!B5 -> 0557 | C5: 44675 | D5: Contract | E5: 70375 | F5: 687 | G5: No | H5: No | I5: Pending | J5: 2134.2 | K5: 3557 | L5: 4 | M5: Referred by agent.
A6: ='Applications (Cleaned)'!A6 -> 02528 | B6: ='Applications (Cleaned)'!B6 -> 0038 | C6: 44243 | D6: Retired | E6: 142283 | G6: Yes | H6: Yes | I6: Pending | J6: 4979.52 | K6: 5187 | L6: 5 | M6: Referred by agent.
A7: ='Applications (Cleaned)'!A7 -> 05110 | B7: ='Applications (Cleaned)'!B7 -> 0483 | C7: 43918 | D7: Self-Employed | E7: 168958 | F7: 676 | G7: No | H7: No | I7: Approved | J7: 1337.28 | K7: 1592 | L7: 2 | M7: Co-signer pending review.
A8: ='Applications (Cleaned)'!A8 -> 08277 | B8: ='Applications (Cleaned)'!B8 -> 0386 | C8: 45320 | D8: Student | E8: 98060 | F8: 833 | G8: No | H8: Yes | I8: Approved | J8: 1518 | K8: 2300 | L8: 2 | M8: Flagged for manual review.
A9: ='Applications (Cleaned)'!A9 -> 08386 | B9: ='Applications (Cleaned)'!B9 -> 1432 | C9: 44092 | D9: Unemployed | E9: 124900 | F9: 698 | G9: No | H9: No | I9: Under Review | J9: 5827.2 | K9: 6070 | L9: 4 | M9: .
A10: ='Applications (Cleaned)'!A10 -> 09442 | B10: ='Applications (Cleaned)'!B10 -> 1532 | C10: 44990 | D10: Full-Time | E10: 44834 | F10: 656 | G10: No | H10: No | I10: Denied | J10: 2118.48 | K10: 2716 | L10: 4 | M10: docs expired
A11: ='Applications (Cleaned)'!A11 -> 10126 | B11: ='Applications (Cleaned)'!B11 -> 0207 | C11: 44519 | D11: Retired | E11: 205761 | F11: 662 | G11: No | H11: Yes | I11: Pending | J11: 3986.4 | K11: 6644 | L11: 5
A12: ='Applications (Cleaned)'!A12 -> 12726 | B12: ='Applications (Cleaned)'!B12 -> 1738 | C12: 45651 | D12: Part-Time | E12: 213156 | G12: No | H12: No | I12: Pending | J12: 1776.6 | K12: 2115 | L12: 3 | M12: docs expired
A13: ='Applications (Cleaned)'!A13 -> 13509 | B13: ='Applications (Cleaned)'!B13 -> 0200 | C13: 44530 | D13: Full-Time | E13: 205434 | G13: Yes | H13: Yes | I13: Approved | J13: 1840.74 | K13: 2789 | L13: 1 | M13: Referred by agent.
A14: ='Applications (Cleaned)'!A14 -> 14294 | B14: ='Applications (Cleaned)'!B14 -> 0030 | C14: 44970 | D14: Unemployed | E14: 231909 | F14: 809 | G14: No | H14: No | I14: Approved | J14: 2976.96 | K14: 3101 | L14: 4 | M14: Missing bank statements.
A15: ='Applications (Cleaned)'!A15 -> 14569 | B15: ='Applications (Cleaned)'!B15 -> 0304 | C15: 45411 | D15: Unemployed | E15: 183128 | F15: 798 | G15: Yes | H15: No | I15: Denied | J15: 1251 | K15: 2085 | L15: 1 | M15: docs expired
A16: ='Applications (Cleaned)'!A16 -> 14590 | B16: ='Applications (Cleaned)'!B16 -> 0071 | C16: 44625 | D16: Full-Time | E16: 135994 | F16: 448 | G16: No | H16: No | I16: Pending | J16: 2827.5 | K16: 3625 | L16: 3
A17: ='Applications (Cleaned)'!A17 -> 16578 | B17: ='Applications (Cleaned)'!B17 -> 0941 | C17: 44135 | D17: Full-Time | E17: 212683 | F17: 654 | G17: Yes | H17: No | I17: Approved | J17: 2230.02 | K17: 2859 | L17: 3
A18: ='Applications (Cleaned)'!A18 -> 17022 | B18: ='Applications (Cleaned)'!B18 -> 1471 | C18: 44026 | D18: Part-Time | E18: 75089 | G18: No | H18: No | I18: Approved | J18: 3880.8 | K18: 4620 | L18: 3 | M18: Applicant provided pay stubs.
A19: ='Applications (Cleaned)'!A19 -> 20568 | B19: ='Applications (Cleaned)'!B19 -> 1143 | C19: 44664 | D19: Retired | E19: 242708 | F19: 497 | G19: No | H19: No | I19: Denied | J19: 2398.08 | K19: 2498 | L19: 1 | M19: Missing bank statements.
A20: ='Applications (Cleaned)'!A20 -> 22043 | B20: ='Applications (Cleaned)'!B20 -> 1082 | C20: 44303 | D20: Part-Time | E20: 167814 | F20: 722 | G20: No | H20: No | I20: Denied | J20: 913.44 | K20: 1384 | L20: 3 | M20: Flagged for manual review.
A21: ='Applications (Cleaned)'!A21 -> 22113 | B21: ='Applications (Cleaned)'!B21 -> 1614 | C21: 44861 | D21: Full-Time | E21: 161093 | F21: 779 | G21: No | H21: Yes | I21: Pending | J21: 6505.8 | K21: 7745 | L21: 1 | M21: Co-signer pending review.
A22: ='Applications (Cleaned)'!A22 -> 22530 | B22: ='Applications (Cleaned)'!B22 -> 0105 | C22: 44922 | D22: Unemployed | E22: 243086 | F22: 811 | G22: No | H22: No | I22: Withdrawn | J22: 4456.92 | K22: 5714 | L22: 1
A23: ='Applications (Cleaned)'!A23 -> 22927 | B23: ='Applications (Cleaned)'!B23 -> 0858 | C23: 44391 | D23: Unemployed | E23: 6344 | F23: 657 | G23: No | H23: No | I23: Denied | J23: 4003.74 | K23: 5133 | L23: 2 | M23: Missing bank statements.
A24: ='Applications (Cleaned)'!A24 -> 23053 | B24: ='Applications (Cleaned)'!B24 -> 0587 | C24: 45339 | D24: Part-Time | E24: 97725 | F24: 447 | G24: No | H24: Yes | I24: Pending | J24: 5443.2 | K24: 5670 | L24: 5 | M24: Co-signer pending review.
A25: ='Applications (Cleaned)'!A25 -> 23531 | B25: ='Applications (Cleaned)'!B25 -> 0623 | D25: Unemployed | E25: 59619 | F25: 770 | G25: No | H25: No | I25: Approved | J25: 7350.72 | K25: 7657 | L25: 2 | M25: Applicant follow-up needed
A26: ='Applications (Cleaned)'!A26 -> 25929 | B26: ='Applications (Cleaned)'!B26 -> 1112 | C26: 45657 | D26: Student | E26: 18094 | G26: No | H26: No | I26: Pending | J26: 1285.68 | K26: 1948 | L26: 3 | M26: Renewal case.
A27: ='Applications (Cleaned)'!A27 -> 27031 | B27: ='Applications (Cleaned)'!B27 -> 1424 | C27: 45094 | D27: Student | E27: 117184 | F27: 842 | G27: Yes | H27: No | I27: Pending | J27: 1940.64 | K27: 2488 | L27: 5
A28: ='Applications (Cleaned)'!A28 -> 28523 | B28: ='Applications (Cleaned)'!B28 -> 0863 | D28: Contract | E28: 129953 | F28: 729 | G28: No | H28: No | I28: Approved | J28: 828.96 | K28: 1256 | L28: 2
A29: ='Applications (Cleaned)'!A29 -> 29155 | B29: ='Applications (Cleaned)'!B29 -> 0117 | C29: 44535 | D29: Student | E29: 67801 | F29: 726 | G29: No | H29: Yes | I29: Denied | J29: 1776.06 | K29: 2691 | L29: 5 | M29: Flagged for manual review.
A30: ='Applications (Cleaned)'!A30 -> 29469 | B30: ='Applications (Cleaned)'!B30 -> 1502 | C30: 43926 | D30: Retired | E30: 205970 | F30: 717 | G30: No | H30: No | I30: Approved | J30: 1761 | K30: 2935 | L30: 1
A31: ='Applications (Cleaned)'!A31 -> 31153 | B31: ='Applications (Cleaned)'!B31 -> 1426 | C31: 45271 | D31: Retired | E31: 239937 | F31: 552 | G31: No | H31: No | I31: Approved | J31: 6846.72 | K31: 7132 | L31: 5 | M31: Missing bank statements.
A32: ='Applications (Cleaned)'!A32 -> 32569 | B32: ='Applications (Cleaned)'!B32 -> 0960 | C32: 44373 | D32: Unemployed | E32: 135402 | F32: 659 | G32: No | H32: No | I32: Denied | J32: 1281.06 | K32: 1941 | L32: 2
A33: ='Applications (Cleaned)'!A33 -> 33505 | B33: ='Applications (Cleaned)'!B33 -> 1374 | C33: 44776 | D33: Student | E33: 123900 | F33: 718 | G33: Yes | H33: No | I33: Denied | J33: 2250.6 | K33: 3751 | L33: 5 | M33: Renewal case.
A34: ='Applications (Cleaned)'!A34 -> 39831 | B34: ='Applications (Cleaned)'!B34 -> 0786 | C34: 45412 | D34: Part-Time | E34: 182546 | G34: No | H34: No | I34: Withdrawn | J34: 1992.48 | K34: 2372 | L34: 4
A35: ='Applications (Cleaned)'!A35 -> 40594 | B35: ='Applications (Cleaned)'!B35 -> 1486 | C35: 44747 | D35: Part-Time | E35: 196804 | F35: 831 | G35: No | H35: No | I35: Pending | J35: 3932.16 | K35: 4096 | L35: 2 | M35: Co-signer pending review.
A36: ='Applications (Cleaned)'!A36 -> 40885 | B36: ='Applications (Cleaned)'!B36 -> 0542 | C36: 45612 | D36: Retired | E36: 79240 | F36: 730 | G36: Yes | H36: Yes | I36: Pending | J36: 1566.6 | K36: 1865 | L36: 3 | M36: Missing bank statements.
A37: ='Applications (Cleaned)'!A37 -> 42664 | B37: ='Applications (Cleaned)'!B37 -> 0690 | C37: 44177 | D37: Unemployed | E37: 73906 | F37: 632 | G37: No | H37: No | I37: Withdrawn | J37: 1048.32 | K37: 1344 | L37: 2 | M37: Missing bank statements.
A38: ='Applications (Cleaned)'!A38 -> 42801 | B38: ='Applications (Cleaned)'!B38 -> 1301 | C38: 44733 | D38: Student | E38: 88287 | F38: 587 | G38: No | H38: Yes | I38: Denied | J38: 1393.92 | K38: 2112 | L38: 5
A39: ='Applications (Cleaned)'!A39 -> 42852 | B39: ='Applications (Cleaned)'!B39 -> 0635 | C39: 45116 | D39: Student | E39: 184446 | F39: 679 | G39: No | H39: No | I39: Approved | J39: 4816.32 | K39: 5017 | L39: 2 | M39: .
A40: ='Applications (Cleaned)'!A40 -> 45209 | B40: ='Applications (Cleaned)'!B40 -> 1679 | C40: 43941 | D40: Student | E40: 155017 | F40: 628 | G40: Yes | H40: No | I40: Withdrawn | J40: 3724.56 | K40: 4434 | L40: 4
...

Sheet Properties
A1: property_id | B1: city | C1: state | D1: zip | E1: unit_type | F1: monthly_rent | G1: landlord_type | H1: lease_length
A2: 1 | B2: Washington | C2: DC | D2: 200XX | E2: 1BR | F2: 851 | G2: LLC | H2: 6 months
A3: 2 | B3: Chicago | C3: IL | D3: 60614 | E3: 3BR | F3: 3081 | G3: LLC | H3: 6 months
A4: 3 | B4: Nashville | C4: TN | D4: 37201 | E4: 1BR | F4: 1426 | G4: Corporate | H4: 12 months
A5: 4 | B5: Nashville | C5: TN | D5: 37206 | E5: 2BR | F5: 1731 | G5: LLC | H5: 12 months
A6: 5 | B6: Los Angeles | C6: CA | D6: 90036 | E6: 4BR+ | F6: 3898 | G6: Individual | H6: 12 months
A7: 7 | B7: Cambridge | C7: MA | D7: 2139 | E7: 2BR | F7: 2586 | G7: LLC | H7: 12 months
A8: 8 | B8: Seattle | C8: WA | D8: 98103 | E8: 3BR | F8: 8826 | G8: Individual | H8: 24 months
A9: 9 | B9: Scottsdale | C9: AZ | D9: 85251 | E9: 1BR | F9: 1641 | G9: Individual | H9: 12 months
A10: 10 | B10: Houston | C10: TX | D10: 77001 | E10: Studio | F10: 2937 | G10: Corporate | H10: 6 months
A11: 11 | B11: Chicago | C11: IL | D11: 60614 | E11: 3BR | F11: 5995 | G11: REIT | H11: 18 months
A12: 12 | B12: Chicago | C12: IL | D12: 60614 | E12: Studio | F12: 1840 | G12: LLC | H12: 12 months
A13: 14 | B13: Atlanta | C13: GA | D13: 30301 | E13: Studio | F13: 2167 | G13: REIT | H13: 12 months
A14: 15 | B14: New York | C14: NY | D14: 10003 | E14: Studio | F14: 2224 | G14: Corporate | H14: 6 months
... A22: 23 | B22: Fort Lauderdale | C22: FL | D22: 33301 | E22: 4BR+ | F22: 3634 | G22: REIT | H22: 12 months
A23: 24 | B23: San Francisco | C23: CA | D23: 94110 | E23: Studio | F23: 2968 | H23: 12 months
A24: 25 | B24: Los Angeles | C24: CA | D24: 90036 | E24: 4BR+ | F24: 7623 | G24: REIT | H24: 24 months
A25: 26 | B25: Atlanta | C25: GA | D25: 30308 | E25: Studio | F25: 1516 | G25: REIT | H25: 24 months
A26: 27 | B26: Los Angeles | C26: CA | D26: 90025 | E26: 1BR | F26: 1542 | G26: LLC | H26: 12 months
A27: 28 | B27: Nashville | C27: TN | D27: 37201 | E27: 2BR | F27: 4252 | G27: REIT | H27: 24 months
A28: 29 | B28: San Francisco | C28: CA | D28: 94110 | E28: 2BR | F28: 2931 | G28: LLC | H28: 12 months
A29: 30 | B29: Queens | C29: NY | D29: 11101 | E29: 1BR | F29: 3101 | G29: LLC | H29: 12 months
A30: 32 | B30: Atlanta | C30: GA | D30: 303XX | E30: 1BR | F30: 1286 | G30: Property Management Co | H30: 24 months
A31: 33 | B31: Nashville | C31: TN | D31: 37206 | E31: Studio | F31: 1110 | G31: Property Management Co | H31: 6 months
A32: 34 | B32: Houston | C32: TX | D32: 77019 | E32: 1BR | F32: 1432 | G32: Corporate | H32: 12 months
A33: 35 | B33: Austin | C33: TX | D33: 78701 | E33: Studio | F33: 1915 | G33: REIT | H33: 12 months
A34: 37 | B34: Bellevue | C34: WA | D34: 98004 | E34: Studio | F34: 1129 | G34: Individual | H34: 18 months
A35: 38 | B35: Cambridge | C35: MA | D35: 2139 | E35: 4BR+ | F35: 5187 | G35: Individual | H35: 12 months
A36: 39 | B36: Scottsdale | C36: AZ | D36: 85251 | E36: 2BR | F36: 3301 | G36: Property Management Co | H36: 12 months
A37: 40 | B37: San Francisco | C37: CA | D37: 94110 | E37: 4BR+ | F37: 11118 | G37: Property Management Co | H37: 24 months
A38: 41 | B38: Arlington | C38: VA | D38: 22201 | E38: 1BR | F38: 1251 | G38: REIT | H38: 12 months
A39: 42 | B39: Nashville | C39: TN | D39: 37206 | E39: 4BR+ | F39: 6997 | G39: Individual | H39: 6 months
A40: 43 | B40: Seattle | C40: WA | D40: 98101 | E40: 2BR | F40: 3294 | G40: REIT | H40: 12 months
A41: 44 | B41: Nashville | C41: TN | D41: 37206 | E41: 4BR+ | F41: 7813 | G41: REIT | H41: 6 months
A42: 45 | B42: San Francisco | C42: CA | D42: 94102 | E42: Studio | F42: 3061 | G42: Individual | H42: 12 months
... A63: 70 | B63: Miami | C63: FL | D63: 33130 | E63: Studio | F63: 1531 | G63: Property Management Co | H63: 12 months
A64: 71 | B64: New York | C64: NY | D64: 100XX | E64: 2BR | F64: 3625 | G64: REIT | H64: 12 months
A65: 72 | B65: Boston | C65: MA | D65: 2101 | E65: 1BR | F65: 3137 | G65: Property Management Co | H65: 12 months
A66: 73 | B66: New York | C66: NY | D66: 10003 | E66: 2BR | F66: 4086 | G66: Individual | H66: 18 months
A67: 74 | B67: New York | C67: NY | D67: 10003 | E67: 4BR+ | F67: 9954 | G67: LLC | H67: 18 months
...

Sheet Properties (Cleaned)
A1: property_id | B1: city | C1: state | D1: unit_type | E1: monthly_rent | F1: landlord_type | G1: lease_length
A2: =TEXT(Properties!A2,"0000") -> 0001 | B2: Washington | C2: DC | D2: 1BR | E2: 851 | F2: LLC | G2: 6 months
A3: =TEXT(Properties!A3,"0000") -> 0002 | B3: Chicago | C3: IL | D3: 3BR | E3: 3081 | F3: LLC | G3: 6 months
A4: =TEXT(Properties!A4,"0000") -> 0003 | B4: Nashville | C4: TN | D4: 1BR | E4: 1426 | F4: Corporate | G4: 12 months
A5: =TEXT(Properties!A5,"0000") -> 0004 | B5: Nashville | C5: TN | D5: 2BR | E5: 1731 | F5: LLC | G5: 12 months
A6: =TEXT(Properties!A6,"0000") -> 0005 | B6: Los Angeles | C6: CA | D6: 4BR+ | E6: 3898 | F6: Individual | G6: 12 months
A7: =TEXT(Properties!A7,"0000") -> 0007 | B7: Cambridge | C7: MA | D7: 2BR | E7: 2586 | F7: LLC | G7: 12 months
A8: =TEXT(Properties!A8,"0000") -> 0008 | B8: Seattle | C8: WA | D8: 3BR | E8: 8826 | F8: Individual | G8: 24 months
A9: =TEXT(Properties!A9,"0000") -> 0009 | B9: Scottsdale | C9: AZ | D9: 1BR | E9: 1641 | F9: Individual | G9: 12 months
A10: =TEXT(Properties!A10,"0000") -> 0010 | B10: Houston | C10: TX | D10: Studio | E10: 2937 | F10: Corporate | G10: 6 months
A11: =TEXT(Properties!A11,"0000") -> 0011 | B11: Chicago | C11: IL | D11: 3BR | E11: 5995 | F11: REIT | G11: 18 months
A12: =TEXT(Properties!A12,"0000") -> 0012 | B12: Chicago | C12: IL | D12: Studio | E12: 1840 | F12: LLC | G12: 12 months
A13: =TEXT(Properties!A13,"0000") -> 0014 | B13: Atlanta | C13: GA | D13: Studio | E13: 2167 | F13: REIT | G13: 12 months
... A22: =TEXT(Properties!A22,"0000") -> 0023 | B22: Fort Lauderdale | C22: FL | D22: 4BR+ | E22: 3634 | F22: REIT | G22: 12 months
A23: =TEXT(Properties!A23,"0000") -> 0024 | B23: San Francisco | C23: CA | D23: Studio | E23: 2968 | G23: 12 months
A24: =TEXT(Properties!A24,"0000") -> 0025 | B24: Los Angeles | C24: CA | D24: 4BR+ | E24: 7623 | F24: REIT | G24: 24 months
A25: =TEXT(Properties!A25,"0000") -> 0026 | B25: Atlanta | C25: GA | D25: Studio | E25: 1516 | F25: REIT | G25: 24 months
A26: =TEXT(Properties!A26,"0000") -> 0027 | B26: Los Angeles | C26: CA | D26: 1BR | E26: 1542 | F26: LLC | G26: 12 months
A27: =TEXT(Properties!A27,"0000") -> 0028 | B27: Nashville | C27: TN | D27: 2BR | E27: 4252 | F27: REIT | G27: 24 months
A28: =TEXT(Properties!A28,"0000") -> 0029 | B28: San Francisco | C28: CA | D28: 2BR | E28: 2931 | F28: LLC | G28: 12 months
A29: =TEXT(Properties!A29,"0000") -> 0030 | B29: Queens | C29: NY | D29: 1BR | E29: 3101 | F29: LLC | G29: 12 months
A30: =TEXT(Properties!A30,"0000") -> 0032 | B30: Atlanta | C30: GA | D30: 1BR | E30: 1286 | F30: Property Management Co | G30: 24 months
A31: =TEXT(Properties!A31,"0000") -> 0033 | B31: Nashville | C31: TN | D31: Studio | E31: 1110 | F31: Property Management Co | G31: 6 months
A32: =TEXT(Properties!A32,"0000") -> 0034 | B32: Houston | C32: TX | D32: 1BR | E32: 1432 | F32: Corporate | G32: 12 months
A33: =TEXT(Properties!A33,"0000") -> 0035 | B33: Austin | C33: TX | D33: Studio | E33: 1915 | F33: REIT | G33: 12 months
A34: =TEXT(Properties!A34,"0000") -> 0037 | B34: Bellevue | C34: WA | D34: Studio | E34: 1129 | F34: Individual | G34: 18 months
A35: =TEXT(Properties!A35,"0000") -> 0038 | B35: Cambridge | C35: MA | D35: 4BR+ | E35: 5187 | F35: Individual | G35: 12 months
... A127: =TEXT(Properties!A127,"0000") -> 0145 | B127: Austin | C127: TX | D127: Studio | E127: 868 | F127: Individual | G127: 12 months
A128: =TEXT(Properties!A128,"0000") -> 0146 | B128: Brooklyn | C128: NY | D128: Studio | E128: 2217 | G128: 6 months
A129: =TEXT(Properties!A129,"0000") -> 0147 | B129: New York | C129: NY | D129: 1BR | E129: 3442 | F129: Property Management Co | G129: 24 months
A130: =TEXT(Properties!A130,"0000") -> 0148 | B130: Nashville | C130: TN | D130: Studio | E130: 975 | F130: Individual | G130: 18 months
A131: =TEXT(Properties!A131,"0000") -> 0149 | B131: Chicago | C131: IL | D131: Studio | E131: 1719 | F131: Individual | G131: 18 months
A132: =TEXT(Properties!A132,"0000") -> 0151 | B132: Fort Lauderdale | C132: FL | D132: 3BR | E132: 3821 | F132: Individual | G132: 12 months
A133: =TEXT(Properties!A133,"0000") -> 0152 | B133: Bellevue | C133: WA | D133: 2BR | E133: 2369 | F133: LLC | G133: 12 months
A134: =TEXT(Properties!A134,"0000") -> 0153 | B134: Brooklyn | C134: NY | D134: 1BR | E134: 4453 | F134: Property Management Co | G134: 12 months
A135: =TEXT(Properties!A135,"0000") -> 0154 | B135: Portland | C135: OR | D135: Studio | E135: 1383 | F135: Individual | G135: 6 months
A136: =TEXT(Properties!A136,"0000") -> 0155 | B136: Houston | C136: TX | D136: 2BR | E136: 4232 | F136: LLC | G136: 12 months
A137: =TEXT(Properties!A137,"0000") -> 0156 | B137: Fort Lauderdale | C137: FL | D137: 2BR | E137: 4287 | F137: Property Management Co | G137: 6 months
A138: =TEXT(Properties!A138,"0000") -> 0157 | B138: San Francisco | C138: CA | D138: 4BR+ | E138: 11068 | F138: REIT | G138: 12 months
A139: =TEXT(Properties!A139,"0000") -> 0158 | B139: Arlington | C139: VA | D139: Studio | E139: 1255 | F139: Property Management Co | G139: 12 months
...
